Workbook

Sheet 1 Data
B2: Probability of Default — the real data
B3: 1,000 real credit-card customers of a Taiwanese bank, with what actually happened next month.
B5: SOURCE: UCI Machine Learning Repository, dataset 350, "Default of Credit Card Clients". Yeh, I. C., & Lien, C. H. (2009), Expert Systems with Applications 36(2), 2473-2480. 30,000 real customers of a bank in Taiwan, April to September 2005. The models were fitted on 21,000 training rows. The 1,000 rows below are a random sample of the 9,000 TEST rows, which the models never saw while training. Default rate: 22.12% across all 30,000, 23.70% in this sample. PAY_0 and PAY_2 are the repayment status last month and two months ago: -2 and -1 mean paid in full or no balance, 0 means paying the minimum, and 1 to 8 is the number of months overdue. UTILISATION is the bill divided by the credit limit. PAY_RATIO is the amount paid divided by the bill.
B11: ID | C11: Credit limit (NT$) | D11: Age | E11: PAY_0 repayment status, last month | F11: PAY_2 repayment status, 2 months ago | G11: Utilisation bill / limit | H11: Pay ratio paid / bill | I11: DEFAULTED? 1 = yes
B12: 18 | C12: 320000 | D12: 49 | E12: 0 | F12: 0 | G12: 0.7915 | H12: 0.0409 | I12: 0
B13: 35 | C13: 500000 | D13: 58 | E13: -2 | F13: -2 | G13: 0.0274 | H13: 0.3652 | I13: 0
B14: 64 | C14: 50000 | D14: 46 | E14: 0 | F14: 0 | G14: 0.5744 | H14: 0.0348 | I14: 1
B15: 189 | C15: 130000 | D15: 34 | E15: 1 | F15: -1 | G15: 0 | H15: 0 | I15: 0
B16: 216 | C16: 30000 | D16: 42 | E16: -1 | F16: -1 | G16: 0.013 | H16: 1 | I16: 0
B17: 224 | C17: 320000 | D17: 33 | E17: 0 | F17: 0 | G17: 0.2864 | H17: 0.1096 | I17: 0
B18: 239 | C18: 240000 | D18: 50 | E18: 0 | F18: 0 | G18: 0.9759 | H18: 0.0432 | I18: 1
B19: 248 | C19: 100000 | D19: 27 | E19: 0 | F19: 0 | G19: 0.3777 | H19: 0.0473 | I19: 0
B20: 288 | C20: 440000 | D20: 46 | E20: 0 | F20: 0 | G20: 0.4105 | H20: 0.0477 | I20: 0
B21: 298 | C21: 210000 | D21: 36 | E21: 0 | F21: 0 | G21: 0.682 | H21: 0.0453 | I21: 0
B22: 343 | C22: 200000 | D22: 29 | E22: -1 | F22: 2 | G22: 0.012 | H22: 0 | I22: 0
B23: 355 | C23: 50000 | D23: 58 | E23: 2 | F23: 2 | G23: 0.318 | H23: 0.2138 | I23: 0
... B1011: 29978 | C1011: 420000 | D1011: 34 | E1011: 0 | F1011: 0 | G1011: 0.3141 | H1011: 0.0531 | I1011: 0

Sheet 2 Logistic Regression
B2: Model 1 — Logistic regression
B3: One weight per variable. Multiply, add, then squash the total into a probability.
B5: Every PD in column D below is computed by an Excel formula from the coefficients in the table above it. Change a coefficient and all 1,000 probabilities move. This is the whole point of a logistic regression: the model fits on one line and anyone can recompute it. The coefficients were fitted in scikit-learn on standardised variables and then converted back to the raw scale, so they apply directly to the numbers on sheet 1. The conversion was checked against scikit-learn's own predictions and matches to nine decimal places.
B11: Variable | C11: Coefficient | D11: What it means | I11: THE FORMULA, WRITTEN OUT
B12: Intercept | C12: -1.2220704 | D12: The starting point before any variable is read. | I12: SCORE = b0 + b1×LIMIT_BAL + b2×AGE + b3×PAY_0 + b4×PAY_2 + b5×UTILISATION + b6×PAY_RATIO 1 PD = ────────────────────── so a score of 0 gives PD 50%, a score of −2 gives PD 12%, a score of +2 gives PD 88%. 1 + e^(−SCORE)
B13: LIMIT_BAL | C13: -2.2087737e-06 | D13: A bigger credit limit lowers the score, so it lowers the PD.
B14: AGE | C14: 0.0086050497 | D14: Age moves the score only slightly.
B15: PAY_0 | C15: 0.63775815 | D15: Last month's delay is the strongest single driver.
B16: PAY_2 | C16: 0.20079116 | D16: The delay two months ago adds to it. | I16: WORKED EXAMPLE — the customer on row 23, term by term
B17: UTILISATION | C17: -0.42280901 | D17: Using more of the limit raises the PD. | I17: Term | J17: Value from sheet 1 | K17: × Coefficient | L17: → Contribution to the score
B18: PAY_RATIO | C18: 0.20359888 | D18: Paying down more of the bill lowers the PD. | I18: Intercept | J18: — | K18: =$C$12 | L18: =$C$12
I19: LIMIT_BAL | J19: ='1 Data'!C12 | K19: =$C$13 | L19: =J19*K19
B20: SCORE = intercept + (each variable × its coefficient). PD = 1 / (1 + EXP(−SCORE)). | I20: AGE | J20: ='1 Data'!D12 | K20: =$C$14 | L20: =J20*K20
I21: PAY_0 | J21: ='1 Data'!E12 | K21: =$C$15 | L21: =J21*K21
B22: ID | C22: Score | D22: PD (probability of default) | E22: Actually defaulted? | F22: Rank | G22: Mid-rank (used by the live AUC) | I22: PAY_2 | J22: ='1 Data'!F12 | K22: =$C$16 | L22: =J22*K22
B23: ='1 Data'!B12 | C23: =$C$12 + '1 Data'!C12*$C$13 + '1 Data'!D12*$C$14 + '1 Data'!E12*$C$15 + '1 Data'!F12*$C$16 + '1 Data'!G12*$C$17 + '1 Data'!H12*$C$18 | D23: =1/(1+EXP(-C23)) | E23: ='1 Data'!I12 | F23: =RANK(D23,$D$23:$D$1022) | G23: =COUNTIF($D$23:$D$1022,"<"&D23)+(COUNTIF($D$23:$D$1022,"="&D23)+1)/2 | I23: UTILISATION | J23: ='1 Data'!G12 | K23: =$C$17 | L23: =J23*K23
B24: ='1 Data'!B13 | C24: =$C$12 + '1 Data'!C13*$C$13 + '1 Data'!D13*$C$14 + '1 Data'!E13*$C$15 + '1 Data'!F13*$C$16 + '1 Data'!G13*$C$17 + '1 Data'!H13*$C$18 | D24: =1/(1+EXP(-C24)) | E24: ='1 Data'!I13 | F24: =RANK(D24,$D$23:$D$1022) | G24: =COUNTIF($D$23:$D$1022,"<"&D24)+(COUNTIF($D$23:$D$1022,"="&D24)+1)/2 | I24: PAY_RATIO | J24: ='1 Data'!H12 | K24: =$C$18 | L24: =J24*K24
B25: ='1 Data'!B14 | C25: =$C$12 + '1 Data'!C14*$C$13 + '1 Data'!D14*$C$14 + '1 Data'!E14*$C$15 + '1 Data'!F14*$C$16 + '1 Data'!G14*$C$17 + '1 Data'!H14*$C$18 | D25: =1/(1+EXP(-C25)) | E25: ='1 Data'!I14 | F25: =RANK(D25,$D$23:$D$1022) | G25: =COUNTIF($D$23:$D$1022,"<"&D25)+(COUNTIF($D$23:$D$1022,"="&D25)+1)/2 | I25: SCORE (add the column) | L25: =SUM(L18:L24)
B26: ='1 Data'!B15 | C26: =$C$12 + '1 Data'!C15*$C$13 + '1 Data'!D15*$C$14 + '1 Data'!E15*$C$15 + '1 Data'!F15*$C$16 + '1 Data'!G15*$C$17 + '1 Data'!H15*$C$18 | D26: =1/(1+EXP(-C26)) | E26: ='1 Data'!I15 | F26: =RANK(D26,$D$23:$D$1022) | G26: =COUNTIF($D$23:$D$1022,"<"&D26)+(COUNTIF($D$23:$D$1022,"="&D26)+1)/2 | I26: PD = 1 / (1 + EXP(−SCORE)) | L26: =1/(1+EXP(-L25))
B27: ='1 Data'!B16 | C27: =$C$12 + '1 Data'!C16*$C$13 + '1 Data'!D16*$C$14 + '1 Data'!E16*$C$15 + '1 Data'!F16*$C$16 + '1 Data'!G16*$C$17 + '1 Data'!H16*$C$18 | D27: =1/(1+EXP(-C27)) | E27: ='1 Data'!I16 | F27: =RANK(D27,$D$23:$D$1022) | G27: =COUNTIF($D$23:$D$1022,"<"&D27)+(COUNTIF($D$23:$D$1022,"="&D27)+1)/2 | I27: =IF(ABS(L26-D23)<0.0000001,"This matches cell D23 exactly, as it must.","MISMATCH — something is wrong")
B28: ='1 Data'!B17 | C28: =$C$12 + '1 Data'!C17*$C$13 + '1 Data'!D17*$C$14 + '1 Data'!E17*$C$15 + '1 Data'!F17*$C$16 + '1 Data'!G17*$C$17 + '1 Data'!H17*$C$18 | D28: =1/(1+EXP(-C28)) | E28: ='1 Data'!I17 | F28: =RANK(D28,$D$23:$D$1022) | G28: =COUNTIF($D$23:$D$1022,"<"&D28)+(COUNTIF($D$23:$D$1022,"="&D28)+1)/2
B29: ='1 Data'!B18 | C29: =$C$12 + '1 Data'!C18*$C$13 + '1 Data'!D18*$C$14 + '1 Data'!E18*$C$15 + '1 Data'!F18*$C$16 + '1 Data'!G18*$C$17 + '1 Data'!H18*$C$18 | D29: =1/(1+EXP(-C29)) | E29: ='1 Data'!I18 | F29: =RANK(D29,$D$23:$D$1022) | G29: =COUNTIF($D$23:$D$1022,"<"&D29)+(COUNTIF($D$23:$D$1022,"="&D29)+1)/2
B30: ='1 Data'!B19 | C30: =$C$12 + '1 Data'!C19*$C$13 + '1 Data'!D19*$C$14 + '1 Data'!E19*$C$15 + '1 Data'!F19*$C$16 + '1 Data'!G19*$C$17 + '1 Data'!H19*$C$18 | D30: =1/(1+EXP(-C30)) | E30: ='1 Data'!I19 | F30: =RANK(D30,$D$23:$D$1022) | G30: =COUNTIF($D$23:$D$1022,"<"&D30)+(COUNTIF($D$23:$D$1022,"="&D30)+1)/2
B31: ='1 Data'!B20 | C31: =$C$12 + '1 Data'!C20*$C$13 + '1 Data'!D20*$C$14 + '1 Data'!E20*$C$15 + '1 Data'!F20*$C$16 + '1 Data'!G20*$C$17 + '1 Data'!H20*$C$18 | D31: =1/(1+EXP(-C31)) | E31: ='1 Data'!I20 | F31: =RANK(D31,$D$23:$D$1022) | G31: =COUNTIF($D$23:$D$1022,"<"&D31)+(COUNTIF($D$23:$D$1022,"="&D31)+1)/2
B32: ='1 Data'!B21 | C32: =$C$12 + '1 Data'!C21*$C$13 + '1 Data'!D21*$C$14 + '1 Data'!E21*$C$15 + '1 Data'!F21*$C$16 + '1 Data'!G21*$C$17 + '1 Data'!H21*$C$18 | D32: =1/(1+EXP(-C32)) | E32: ='1 Data'!I21 | F32: =RANK(D32,$D$23:$D$1022) | G32: =COUNTIF($D$23:$D$1022,"<"&D32)+(COUNTIF($D$23:$D$1022,"="&D32)+1)/2
B33: ='1 Data'!B22 | C33: =$C$12 + '1 Data'!C22*$C$13 + '1 Data'!D22*$C$14 + '1 Data'!E22*$C$15 + '1 Data'!F22*$C$16 + '1 Data'!G22*$C$17 + '1 Data'!H22*$C$18 | D33: =1/(1+EXP(-C33)) | E33: ='1 Data'!I22 | F33: =RANK(D33,$D$23:$D$1022) | G33: =COUNTIF($D$23:$D$1022,"<"&D33)+(COUNTIF($D$23:$D$1022,"="&D33)+1)/2
B34: ='1 Data'!B23 | C34: =$C$12 + '1 Data'!C23*$C$13 + '1 Data'!D23*$C$14 + '1 Data'!E23*$C$15 + '1 Data'!F23*$C$16 + '1 Data'!G23*$C$17 + '1 Data'!H23*$C$18 | D34: =1/(1+EXP(-C34)) | E34: ='1 Data'!I23 | F34: =RANK(D34,$D$23:$D$1022) | G34: =COUNTIF($D$23:$D$1022,"<"&D34)+(COUNTIF($D$23:$D$1022,"="&D34)+1)/2
B35: ='1 Data'!B24 | C35: =$C$12 + '1 Data'!C24*$C$13 + '1 Data'!D24*$C$14 + '1 Data'!E24*$C$15 + '1 Data'!F24*$C$16 + '1 Data'!G24*$C$17 + '1 Data'!H24*$C$18 | D35: =1/(1+EXP(-C35)) | E35: ='1 Data'!I24 | F35: =RANK(D35,$D$23:$D$1022) | G35: =COUNTIF($D$23:$D$1022,"<"&D35)+(COUNTIF($D$23:$D$1022,"="&D35)+1)/2
B36: ='1 Data'!B25 | C36: =$C$12 + '1 Data'!C25*$C$13 + '1 Data'!D25*$C$14 + '1 Data'!E25*$C$15 + '1 Data'!F25*$C$16 + '1 Data'!G25*$C$17 + '1 Data'!H25*$C$18 | D36: =1/(1+EXP(-C36)) | E36: ='1 Data'!I25 | F36: =RANK(D36,$D$23:$D$1022) | G36: =COUNTIF($D$23:$D$1022,"<"&D36)+(COUNTIF($D$23:$D$1022,"="&D36)+1)/2
B37: ='1 Data'!B26 | C37: =$C$12 + '1 Data'!C26*$C$13 + '1 Data'!D26*$C$14 + '1 Data'!E26*$C$15 + '1 Data'!F26*$C$16 + '1 Data'!G26*$C$17 + '1 Data'!H26*$C$18 | D37: =1/(1+EXP(-C37)) | E37: ='1 Data'!I26 | F37: =RANK(D37,$D$23:$D$1022) | G37: =COUNTIF($D$23:$D$1022,"<"&D37)+(COUNTIF($D$23:$D$1022,"="&D37)+1)/2
B38: ='1 Data'!B27 | C38: =$C$12 + '1 Data'!C27*$C$13 + '1 Data'!D27*$C$14 + '1 Data'!E27*$C$15 + '1 Data'!F27*$C$16 + '1 Data'!G27*$C$17 + '1 Data'!H27*$C$18 | D38: =1/(1+EXP(-C38)) | E38: ='1 Data'!I27 | F38: =RANK(D38,$D$23:$D$1022) | G38: =COUNTIF($D$23:$D$1022,"<"&D38)+(COUNTIF($D$23:$D$1022,"="&D38)+1)/2
B39: ='1 Data'!B28 | C39: =$C$12 + '1 Data'!C28*$C$13 + '1 Data'!D28*$C$14 + '1 Data'!E28*$C$15 + '1 Data'!F28*$C$16 + '1 Data'!G28*$C$17 + '1 Data'!H28*$C$18 | D39: =1/(1+EXP(-C39)) | E39: ='1 Data'!I28 | F39: =RANK(D39,$D$23:$D$1022) | G39: =COUNTIF($D$23:$D$1022,"<"&D39)+(COUNTIF($D$23:$D$1022,"="&D39)+1)/2
... B1022: ='1 Data'!B1011 | C1022: =$C$12 + '1 Data'!C1011*$C$13 + '1 Data'!D1011*$C$14 + '1 Data'!E1011*$C$15 + '1 Data'!F1011*$C$16 + '1 Data'!G1011*$C$17 + '1 Data'!H1011*$C$18 | D1022: =1/(1+EXP(-C1022)) | E1022: ='1 Data'!I1011 | F1022: =RANK(D1022,$D$23:$D$1022) | G1022: =COUNTIF($D$23:$D$1022,"<"&D1022)+(COUNTIF($D$23:$D$1022,"="&D1022)+1)/2

Sheet 3 Decision Tree
B2: Model 2 — Decision tree
B3: A flowchart of yes-or-no questions. Every customer falls into exactly one box.
B5: The tree was grown to a depth of three, which gives the seven boxes below. There is no equation behind a box. Its PD is simply the share of the TRAINING customers in that box who went on to default: PD = defaulted / customers, and column F computes exactly that. Box 2 holds 15,386 customers of whom 1,992 defaulted, so its PD is 12.95%. Anyone new who lands in box 2 is given that same 12.95%. Column C finds the box with a nested IF, and column D looks up that box's PD. Both are live formulas, so a tree is still something you can rebuild inside a spreadsheet. That stops being true for the next model.
B11: Box | C11: Defaulted | D11: Did not | E11: Customers in it | F11: PD of that box = defaulted / customers | G11: Rule — a customer lands here when | H11: THE FORMULA — the whole tree is one nested IF
B12: 1 | C12: 448 | D12: 1375 | E12: =C12+D12 | F12: =C12/E12 | G12: PAY_0 <= 1.5 and PAY_2 <= 1.5 and UTILISATION <= 0.0003 | H12: IF PAY_0 ≤ 1.5 THEN IF PAY_2 ≤ 1.5 THEN ( UTILISATION ≤ 0.0003 → Box 1, else Box 2 ) ELSE ( LIMIT_BAL ≤ 165,000 → Box 3, else Box 4 ) ELSE IF UTILISATION ≤ 0.0652 THEN Box 5 ELSE ( UTILISATION ≤ 0.716 → Box 6, else Box 7 ) Then look up that box's PD in the table on the left. Column C does the first part, column D the second.
B13: 2 | C13: 1992 | D13: 13394 | E13: =C13+D13 | F13: =C13/E13 | G13: PAY_0 <= 1.5 and PAY_2 <= 1.5 and UTILISATION > 0.0003
B14: 3 | C14: 567 | D14: 683 | E14: =C14+D14 | F14: =C14/E14 | G14: PAY_0 <= 1.5 and PAY_2 > 1.5 and LIMIT_BAL <= 165000
B15: 4 | C15: 106 | D15: 240 | E15: =C15+D15 | F15: =C15/E15 | G15: PAY_0 <= 1.5 and PAY_2 > 1.5 and LIMIT_BAL > 165000
B16: 5 | C16: 141 | D16: 111 | E16: =C16+D16 | F16: =C16/E16 | G16: PAY_0 > 1.5 and UTILISATION <= 0.0652
B17: 6 | C17: 646 | D17: 197 | E17: =C17+D17 | F17: =C17/E17 | G17: PAY_0 > 1.5 and UTILISATION > 0.0652 and UTILISATION <= 0.716
B18: 7 | C18: 745 | D18: 355 | E18: =C18+D18 | F18: =C18/E18 | G18: PAY_0 > 1.5 and UTILISATION > 0.0652 and UTILISATION > 0.716
B22: ID | C22: Box it lands in | D22: PD (probability of default) | E22: Actually defaulted? | F22: Mid-rank
B23: ='1 Data'!B12 | C23: =IF('1 Data'!E12<=1.5,IF('1 Data'!F12<=1.5,IF('1 Data'!G12<=0.0003,1,2),IF('1 Data'!C12<=165000,3,4)),IF('1 Data'!G12<=0.0652,5,IF('1 Data'!G12<=0.716,6,7))) | D23: =INDEX($F$12:$F$18,C23) | E23: ='1 Data'!I12 | F23: =COUNTIF($D$23:$D$1022,"<"&D23)+(COUNTIF($D$23:$D$1022,"="&D23)+1)/2
B24: ='1 Data'!B13 | C24: =IF('1 Data'!E13<=1.5,IF('1 Data'!F13<=1.5,IF('1 Data'!G13<=0.0003,1,2),IF('1 Data'!C13<=165000,3,4)),IF('1 Data'!G13<=0.0652,5,IF('1 Data'!G13<=0.716,6,7))) | D24: =INDEX($F$12:$F$18,C24) | E24: ='1 Data'!I13 | F24: =COUNTIF($D$23:$D$1022,"<"&D24)+(COUNTIF($D$23:$D$1022,"="&D24)+1)/2
B25: ='1 Data'!B14 | C25: =IF('1 Data'!E14<=1.5,IF('1 Data'!F14<=1.5,IF('1 Data'!G14<=0.0003,1,2),IF('1 Data'!C14<=165000,3,4)),IF('1 Data'!G14<=0.0652,5,IF('1 Data'!G14<=0.716,6,7))) | D25: =INDEX($F$12:$F$18,C25) | E25: ='1 Data'!I14 | F25: =COUNTIF($D$23:$D$1022,"<"&D25)+(COUNTIF($D$23:$D$1022,"="&D25)+1)/2
B26: ='1 Data'!B15 | C26: =IF('1 Data'!E15<=1.5,IF('1 Data'!F15<=1.5,IF('1 Data'!G15<=0.0003,1,2),IF('1 Data'!C15<=165000,3,4)),IF('1 Data'!G15<=0.0652,5,IF('1 Data'!G15<=0.716,6,7))) | D26: =INDEX($F$12:$F$18,C26) | E26: ='1 Data'!I15 | F26: =COUNTIF($D$23:$D$1022,"<"&D26)+(COUNTIF($D$23:$D$1022,"="&D26)+1)/2
B27: ='1 Data'!B16 | C27: =IF('1 Data'!E16<=1.5,IF('1 Data'!F16<=1.5,IF('1 Data'!G16<=0.0003,1,2),IF('1 Data'!C16<=165000,3,4)),IF('1 Data'!G16<=0.0652,5,IF('1 Data'!G16<=0.716,6,7))) | D27: =INDEX($F$12:$F$18,C27) | E27: ='1 Data'!I16 | F27: =COUNTIF($D$23:$D$1022,"<"&D27)+(COUNTIF($D$23:$D$1022,"="&D27)+1)/2
B28: ='1 Data'!B17 | C28: =IF('1 Data'!E17<=1.5,IF('1 Data'!F17<=1.5,IF('1 Data'!G17<=0.0003,1,2),IF('1 Data'!C17<=165000,3,4)),IF('1 Data'!G17<=0.0652,5,IF('1 Data'!G17<=0.716,6,7))) | D28: =INDEX($F$12:$F$18,C28) | E28: ='1 Data'!I17 | F28: =COUNTIF($D$23:$D$1022,"<"&D28)+(COUNTIF($D$23:$D$1022,"="&D28)+1)/2
B29: ='1 Data'!B18 | C29: =IF('1 Data'!E18<=1.5,IF('1 Data'!F18<=1.5,IF('1 Data'!G18<=0.0003,1,2),IF('1 Data'!C18<=165000,3,4)),IF('1 Data'!G18<=0.0652,5,IF('1 Data'!G18<=0.716,6,7))) | D29: =INDEX($F$12:$F$18,C29) | E29: ='1 Data'!I18 | F29: =COUNTIF($D$23:$D$1022,"<"&D29)+(COUNTIF($D$23:$D$1022,"="&D29)+1)/2
B30: ='1 Data'!B19 | C30: =IF('1 Data'!E19<=1.5,IF('1 Data'!F19<=1.5,IF('1 Data'!G19<=0.0003,1,2),IF('1 Data'!C19<=165000,3,4)),IF('1 Data'!G19<=0.0652,5,IF('1 Data'!G19<=0.716,6,7))) | D30: =INDEX($F$12:$F$18,C30) | E30: ='1 Data'!I19 | F30: =COUNTIF($D$23:$D$1022,"<"&D30)+(COUNTIF($D$23:$D$1022,"="&D30)+1)/2
B31: ='1 Data'!B20 | C31: =IF('1 Data'!E20<=1.5,IF('1 Data'!F20<=1.5,IF('1 Data'!G20<=0.0003,1,2),IF('1 Data'!C20<=165000,3,4)),IF('1 Data'!G20<=0.0652,5,IF('1 Data'!G20<=0.716,6,7))) | D31: =INDEX($F$12:$F$18,C31) | E31: ='1 Data'!I20 | F31: =COUNTIF($D$23:$D$1022,"<"&D31)+(COUNTIF($D$23:$D$1022,"="&D31)+1)/2
B32: ='1 Data'!B21 | C32: =IF('1 Data'!E21<=1.5,IF('1 Data'!F21<=1.5,IF('1 Data'!G21<=0.0003,1,2),IF('1 Data'!C21<=165000,3,4)),IF('1 Data'!G21<=0.0652,5,IF('1 Data'!G21<=0.716,6,7))) | D32: =INDEX($F$12:$F$18,C32) | E32: ='1 Data'!I21 | F32: =COUNTIF($D$23:$D$1022,"<"&D32)+(COUNTIF($D$23:$D$1022,"="&D32)+1)/2
B33: ='1 Data'!B22 | C33: =IF('1 Data'!E22<=1.5,IF('1 Data'!F22<=1.5,IF('1 Data'!G22<=0.0003,1,2),IF('1 Data'!C22<=165000,3,4)),IF('1 Data'!G22<=0.0652,5,IF('1 Data'!G22<=0.716,6,7))) | D33: =INDEX($F$12:$F$18,C33) | E33: ='1 Data'!I22 | F33: =COUNTIF($D$23:$D$1022,"<"&D33)+(COUNTIF($D$23:$D$1022,"="&D33)+1)/2
B34: ='1 Data'!B23 | C34: =IF('1 Data'!E23<=1.5,IF('1 Data'!F23<=1.5,IF('1 Data'!G23<=0.0003,1,2),IF('1 Data'!C23<=165000,3,4)),IF('1 Data'!G23<=0.0652,5,IF('1 Data'!G23<=0.716,6,7))) | D34: =INDEX($F$12:$F$18,C34) | E34: ='1 Data'!I23 | F34: =COUNTIF($D$23:$D$1022,"<"&D34)+(COUNTIF($D$23:$D$1022,"="&D34)+1)/2
... B1022: ='1 Data'!B1011 | C1022: =IF('1 Data'!E1011<=1.5,IF('1 Data'!F1011<=1.5,IF('1 Data'!G1011<=0.0003,1,2),IF('1 Data'!C1011<=165000,3,4)),IF('1 Data'!G1011<=0.0652,5,IF('1 Data'!G1011<=0.716,6,7))) | D1022: =INDEX($F$12:$F$18,C1022) | E1022: ='1 Data'!I1011 | F1022: =COUNTIF($D$23:$D$1022,"<"&D1022)+(COUNTIF($D$23:$D$1022,"="&D1022)+1)/2

Sheet 4 XGBoost
B2: Model 3 — XGBoost
B3: 200 small trees, each one correcting the mistakes of the trees before it.
B5: Look at column C. Unlike the two sheets before this one, these probabilities are NOT Excel formulas. They are values computed in Python and pasted in. That is not laziness. XGBoost built 200 trees of depth 3, which is up to 1,600 leaves. Every customer's score is the sum of 200 separate leaf values passed through a logistic curve. There is no single line you can print, no coefficient to point at, and no way to write it in a cell. This is the trade in the Module 5 slide, made concrete. The model below is the most accurate of the three. It is also the only one you cannot hand to a customer and say 'here is the number that decided it'.
F11: Variable | G11: Importance
F12: PAY_0 | G12: 0.6117
F13: PAY_2 | G13: 0.2412
F14: LIMIT_BAL | G14: 0.0492
F15: UTILISATION | G15: 0.0439
F16: PAY_RATIO | G16: 0.033
F17: AGE | G17: 0.021
F19: Importance says which variables the 200 trees split on most. It does not say which way they pushed, and it says nothing about any single customer. For that you need SHAP.
B22: ID | C22: PD (probability of default) | D22: Actually defaulted? | E22: Mid-rank
B23: ='1 Data'!B12 | C23: 0.10365988 | D23: ='1 Data'!I12 | E23: =COUNTIF($C$23:$C$1022,"<"&C23)+(COUNTIF($C$23:$C$1022,"="&C23)+1)/2
B24: ='1 Data'!B13 | C24: 0.057915352 | D24: ='1 Data'!I13 | E24: =COUNTIF($C$23:$C$1022,"<"&C24)+(COUNTIF($C$23:$C$1022,"="&C24)+1)/2
B25: ='1 Data'!B14 | C25: 0.16130908 | D25: ='1 Data'!I14 | E25: =COUNTIF($C$23:$C$1022,"<"&C25)+(COUNTIF($C$23:$C$1022,"="&C25)+1)/2
B26: ='1 Data'!B15 | C26: 0.24453694 | D26: ='1 Data'!I15 | E26: =COUNTIF($C$23:$C$1022,"<"&C26)+(COUNTIF($C$23:$C$1022,"="&C26)+1)/2
B27: ='1 Data'!B16 | C27: 0.3061993 | D27: ='1 Data'!I16 | E27: =COUNTIF($C$23:$C$1022,"<"&C27)+(COUNTIF($C$23:$C$1022,"="&C27)+1)/2
B28: ='1 Data'!B17 | C28: 0.05026396 | D28: ='1 Data'!I17 | E28: =COUNTIF($C$23:$C$1022,"<"&C28)+(COUNTIF($C$23:$C$1022,"="&C28)+1)/2
B29: ='1 Data'!B18 | C29: 0.12001652 | D29: ='1 Data'!I18 | E29: =COUNTIF($C$23:$C$1022,"<"&C29)+(COUNTIF($C$23:$C$1022,"="&C29)+1)/2
B30: ='1 Data'!B19 | C30: 0.10451058 | D30: ='1 Data'!I19 | E30: =COUNTIF($C$23:$C$1022,"<"&C30)+(COUNTIF($C$23:$C$1022,"="&C30)+1)/2
B31: ='1 Data'!B20 | C31: 0.05585248 | D31: ='1 Data'!I20 | E31: =COUNTIF($C$23:$C$1022,"<"&C31)+(COUNTIF($C$23:$C$1022,"="&C31)+1)/2
B32: ='1 Data'!B21 | C32: 0.10030016 | D32: ='1 Data'!I21 | E32: =COUNTIF($C$23:$C$1022,"<"&C32)+(COUNTIF($C$23:$C$1022,"="&C32)+1)/2
B33: ='1 Data'!B22 | C33: 0.31261957 | D33: ='1 Data'!I22 | E33: =COUNTIF($C$23:$C$1022,"<"&C33)+(COUNTIF($C$23:$C$1022,"="&C33)+1)/2
B34: ='1 Data'!B23 | C34: 0.74273837 | D34: ='1 Data'!I23 | E34: =COUNTIF($C$23:$C$1022,"<"&C34)+(COUNTIF($C$23:$C$1022,"="&C34)+1)/2
... B1022: ='1 Data'!B1011 | C1022: 0.03988545 | D1022: ='1 Data'!I1011 | E1022: =COUNTIF($C$23:$C$1022,"<"&C1022)+(COUNTIF($C$23:$C$1022,"="&C1022)+1)/2
B1024: Source: xgboost 2.1.4, XGBClassifier(n_estimators=200, max_depth=3, learning_rate=0.1, subsample=0.9, colsample_bytree=0.9, random_state=42), fitted on the 21,000 training rows of UCI dataset 350. Script: fit_models.py.

Sheet 5 Compare
B2: All three models, side by side
B3: Which one ranks best, and what does each one cost you at a real cut-off?
B5: Every number on this sheet is live. AUC and KS come from the formulas on sheet 6, computed over the 1,000 scored customers. The bottom half recomputes too: change the cut-off in the yellow cell and every confusion matrix recomputes with COUNTIFS across the three model sheets. Read the gap. XGBoost wins on every measure, and it wins by about five points of AUC. That is a real edge and it is smaller than most people expect. It is also the model you cannot explain to the customer you declined.
B11: Model | C11: AUC | D11: Gini | E11: KS | F11: Can you write it in a cell?
B12: Logistic Regression | C12: ='6 AUC and KS live'!C15 | D12: =2*C12-1 | E12: ='6 AUC and KS live'!J23 | F12: Yes — one line, six coefficients
B13: Decision Tree | C13: ='6 AUC and KS live'!C35 | D13: =2*C13-1 | E13: ='6 AUC and KS live'!J43 | F13: Yes — seven nested IF conditions
B14: XGBoost | C14: ='6 AUC and KS live'!C55 | D14: =2*C14-1 | E14: ='6 AUC and KS live'!J63 | F14: No — 200 trees, up to 1,600 leaves
B16: AUC and KS are now live formulas on sheet 6, computed over the 1,000 scored customers. Gini is =2*AUC-1. Nothing on this row is typed in.
B18: CUT-OFF — decline everyone whose PD is at or above this | F18: 0.3 | G18: change me
B20: Model | C20: Declined | D20: Approved | E20: Defaults caught | F20: Defaults missed | G20: Good customers refused | H20: Bad rate among approved
B21: Logistic Regression | C21: =COUNTIF('2 Logistic Regression'!$D$23:$D$1022,">="&$F$18) | D21: =COUNTIF('2 Logistic Regression'!$D$23:$D$1022,"<"&$F$18) | E21: =COUNTIFS('2 Logistic Regression'!$D$23:$D$1022,">="&$F$18,'1 Data'!$I$12:$I$1011,1) | F21: =COUNTIFS('2 Logistic Regression'!$D$23:$D$1022,"<"&$F$18,'1 Data'!$I$12:$I$1011,1) | G21: =COUNTIFS('2 Logistic Regression'!$D$23:$D$1022,">="&$F$18,'1 Data'!$I$12:$I$1011,0) | H21: =IFERROR(COUNTIFS('2 Logistic Regression'!$D$23:$D$1022,"<"&$F$18,'1 Data'!$I$12:$I$1011,1)/D21,0)
B22: Decision Tree | C22: =COUNTIF('3 Decision Tree'!$D$23:$D$1022,">="&$F$18) | D22: =COUNTIF('3 Decision Tree'!$D$23:$D$1022,"<"&$F$18) | E22: =COUNTIFS('3 Decision Tree'!$D$23:$D$1022,">="&$F$18,'1 Data'!$I$12:$I$1011,1) | F22: =COUNTIFS('3 Decision Tree'!$D$23:$D$1022,"<"&$F$18,'1 Data'!$I$12:$I$1011,1) | G22: =COUNTIFS('3 Decision Tree'!$D$23:$D$1022,">="&$F$18,'1 Data'!$I$12:$I$1011,0) | H22: =IFERROR(COUNTIFS('3 Decision Tree'!$D$23:$D$1022,"<"&$F$18,'1 Data'!$I$12:$I$1011,1)/D22,0)
B23: XGBoost | C23: =COUNTIF('4 XGBoost'!$C$23:$C$1022,">="&$F$18) | D23: =COUNTIF('4 XGBoost'!$C$23:$C$1022,"<"&$F$18) | E23: =COUNTIFS('4 XGBoost'!$C$23:$C$1022,">="&$F$18,'1 Data'!$I$12:$I$1011,1) | F23: =COUNTIFS('4 XGBoost'!$C$23:$C$1022,"<"&$F$18,'1 Data'!$I$12:$I$1011,1) | G23: =COUNTIFS('4 XGBoost'!$C$23:$C$1022,">="&$F$18,'1 Data'!$I$12:$I$1011,0) | H23: =IFERROR(COUNTIFS('4 XGBoost'!$C$23:$C$1022,"<"&$F$18,'1 Data'!$I$12:$I$1011,1)/D23,0)
B25: Computed live over the 1,000 sampled test customers on sheet 1. "Defaults caught" is the bank avoiding a loss. "Good customers refused" is the bank losing business it should have written. Moving the cut-off trades one against the other, and that trade is a commercial decision, not a modelling one.

Sheet 6 AUC and KS live
B2: AUC, Gini and KS — computed by Excel, not pasted in
B3: Every number on this sheet is a formula over the 1,000 scored customers.
B5: AUC is computed the way a statistician defines it. Rank all 1,000 customers by PD, add up the ranks of the ones who actually defaulted, and compare that total with the best and worst it could possibly be. The mid-rank columns on sheets 2, 3 and 4 do the ranking, and they handle ties by splitting them. The band tables below build the curve that KS is measured on. Each band counts how many customers fell in it and how many of those defaulted, then tracks what share of all bad customers and all good customers you have picked up as you move down from the riskiest band. KS is the widest gap between those two running totals. One honest caveat on KS. These tables use ten bands of width 0.1, so the widest gap can only be found at a band edge. The textbook KS looks at every possible cut-off, so it is always the same or a little higher than the figure below. Narrow the bands and the two converge. AUC has no such issue: the rank method below is exact. Change a coefficient on sheet 2 and every number on this sheet moves.
B11: Logistic Regression
B12: Bad customers (defaulted) | C12: =SUM('2 Logistic Regression'!$E$23:$E$1022) | D12: From | E12: To | F12: Customers | G12: Bad | H12: Good | I12: Cum % of bad | J12: Cum % of good | K12: Gap
B13: Good customers | C13: =COUNT('2 Logistic Regression'!$E$23:$E$1022)-C12 | D13: 0.9 | E13: 1 | F13: =COUNTIFS('2 Logistic Regression'!$D$23:$D$1022,">="&D13,'2 Logistic Regression'!$D$23:$D$1022,"<"&E13) | G13: =COUNTIFS('2 Logistic Regression'!$D$23:$D$1022,">="&D13,'2 Logistic Regression'!$D$23:$D$1022,"<"&E13,'2 Logistic Regression'!$E$23:$E$1022,1) | H13: =F13-G13 | I13: =SUM($G$13:G13)/SUM($G$13:$G$22) | J13: =SUM($H$13:H13)/SUM($H$13:$H$22) | K13: =I13-J13
B14: Sum of the bad customers' ranks | C14: =SUMPRODUCT('2 Logistic Regression'!$G$23:$G$1022,'2 Logistic Regression'!$E$23:$E$1022) | D14: 0.8 | E14: 0.9 | F14: =COUNTIFS('2 Logistic Regression'!$D$23:$D$1022,">="&D14,'2 Logistic Regression'!$D$23:$D$1022,"<"&E14) | G14: =COUNTIFS('2 Logistic Regression'!$D$23:$D$1022,">="&D14,'2 Logistic Regression'!$D$23:$D$1022,"<"&E14,'2 Logistic Regression'!$E$23:$E$1022,1) | H14: =F14-G14 | I14: =SUM($G$13:G14)/SUM($G$13:$G$22) | J14: =SUM($H$13:H14)/SUM($H$13:$H$22) | K14: =I14-J14
B15: AUC | C15: =(C14-C12*(C12+1)/2)/(C12*C13) | D15: 0.7 | E15: 0.8 | F15: =COUNTIFS('2 Logistic Regression'!$D$23:$D$1022,">="&D15,'2 Logistic Regression'!$D$23:$D$1022,"<"&E15) | G15: =COUNTIFS('2 Logistic Regression'!$D$23:$D$1022,">="&D15,'2 Logistic Regression'!$D$23:$D$1022,"<"&E15,'2 Logistic Regression'!$E$23:$E$1022,1) | H15: =F15-G15 | I15: =SUM($G$13:G15)/SUM($G$13:$G$22) | J15: =SUM($H$13:H15)/SUM($H$13:$H$22) | K15: =I15-J15
B16: Gini = 2 × AUC − 1 | C16: =2*C15-1 | D16: 0.6 | E16: 0.7 | F16: =COUNTIFS('2 Logistic Regression'!$D$23:$D$1022,">="&D16,'2 Logistic Regression'!$D$23:$D$1022,"<"&E16) | G16: =COUNTIFS('2 Logistic Regression'!$D$23:$D$1022,">="&D16,'2 Logistic Regression'!$D$23:$D$1022,"<"&E16,'2 Logistic Regression'!$E$23:$E$1022,1) | H16: =F16-G16 | I16: =SUM($G$13:G16)/SUM($G$13:$G$22) | J16: =SUM($H$13:H16)/SUM($H$13:$H$22) | K16: =I16-J16
D17: 0.5 | E17: 0.6 | F17: =COUNTIFS('2 Logistic Regression'!$D$23:$D$1022,">="&D17,'2 Logistic Regression'!$D$23:$D$1022,"<"&E17) | G17: =COUNTIFS('2 Logistic Regression'!$D$23:$D$1022,">="&D17,'2 Logistic Regression'!$D$23:$D$1022,"<"&E17,'2 Logistic Regression'!$E$23:$E$1022,1) | H17: =F17-G17 | I17: =SUM($G$13:G17)/SUM($G$13:$G$22) | J17: =SUM($H$13:H17)/SUM($H$13:$H$22) | K17: =I17-J17
D18: 0.4 | E18: 0.5 | F18: =COUNTIFS('2 Logistic Regression'!$D$23:$D$1022,">="&D18,'2 Logistic Regression'!$D$23:$D$1022,"<"&E18) | G18: =COUNTIFS('2 Logistic Regression'!$D$23:$D$1022,">="&D18,'2 Logistic Regression'!$D$23:$D$1022,"<"&E18,'2 Logistic Regression'!$E$23:$E$1022,1) | H18: =F18-G18 | I18: =SUM($G$13:G18)/SUM($G$13:$G$22) | J18: =SUM($H$13:H18)/SUM($H$13:$H$22) | K18: =I18-J18
D19: 0.3 | E19: 0.4 | F19: =COUNTIFS('2 Logistic Regression'!$D$23:$D$1022,">="&D19,'2 Logistic Regression'!$D$23:$D$1022,"<"&E19) | G19: =COUNTIFS('2 Logistic Regression'!$D$23:$D$1022,">="&D19,'2 Logistic Regression'!$D$23:$D$1022,"<"&E19,'2 Logistic Regression'!$E$23:$E$1022,1) | H19: =F19-G19 | I19: =SUM($G$13:G19)/SUM($G$13:$G$22) | J19: =SUM($H$13:H19)/SUM($H$13:$H$22) | K19: =I19-J19
D20: 0.2 | E20: 0.3 | F20: =COUNTIFS('2 Logistic Regression'!$D$23:$D$1022,">="&D20,'2 Logistic Regression'!$D$23:$D$1022,"<"&E20) | G20: =COUNTIFS('2 Logistic Regression'!$D$23:$D$1022,">="&D20,'2 Logistic Regression'!$D$23:$D$1022,"<"&E20,'2 Logistic Regression'!$E$23:$E$1022,1) | H20: =F20-G20 | I20: =SUM($G$13:G20)/SUM($G$13:$G$22) | J20: =SUM($H$13:H20)/SUM($H$13:$H$22) | K20: =I20-J20
D21: 0.1 | E21: 0.2 | F21: =COUNTIFS('2 Logistic Regression'!$D$23:$D$1022,">="&D21,'2 Logistic Regression'!$D$23:$D$1022,"<"&E21) | G21: =COUNTIFS('2 Logistic Regression'!$D$23:$D$1022,">="&D21,'2 Logistic Regression'!$D$23:$D$1022,"<"&E21,'2 Logistic Regression'!$E$23:$E$1022,1) | H21: =F21-G21 | I21: =SUM($G$13:G21)/SUM($G$13:$G$22) | J21: =SUM($H$13:H21)/SUM($H$13:$H$22) | K21: =I21-J21
D22: 0 | E22: 0.1 | F22: =COUNTIFS('2 Logistic Regression'!$D$23:$D$1022,">="&D22,'2 Logistic Regression'!$D$23:$D$1022,"<="&E22) | G22: =COUNTIFS('2 Logistic Regression'!$D$23:$D$1022,">="&D22,'2 Logistic Regression'!$D$23:$D$1022,"<="&E22,'2 Logistic Regression'!$E$23:$E$1022,1) | H22: =F22-G22 | I22: =SUM($G$13:G22)/SUM($G$13:$G$22) | J22: =SUM($H$13:H22)/SUM($H$13:$H$22) | K22: =I22-J22
I23: KS = | J23: =MAX(K13:K22) | K23: widest gap
B31: Decision Tree
B32: Bad customers (defaulted) | C32: =SUM('3 Decision Tree'!$E$23:$E$1022) | D32: From | E32: To | F32: Customers | G32: Bad | H32: Good | I32: Cum % of bad | J32: Cum % of good | K32: Gap
B33: Good customers | C33: =COUNT('3 Decision Tree'!$E$23:$E$1022)-C32 | D33: 0.9 | E33: 1 | F33: =COUNTIFS('3 Decision Tree'!$D$23:$D$1022,">="&D33,'3 Decision Tree'!$D$23:$D$1022,"<"&E33) | G33: =COUNTIFS('3 Decision Tree'!$D$23:$D$1022,">="&D33,'3 Decision Tree'!$D$23:$D$1022,"<"&E33,'3 Decision Tree'!$E$23:$E$1022,1) | H33: =F33-G33 | I33: =SUM($G$33:G33)/SUM($G$33:$G$42) | J33: =SUM($H$33:H33)/SUM($H$33:$H$42) | K33: =I33-J33
B34: Sum of the bad customers' ranks | C34: =SUMPRODUCT('3 Decision Tree'!$F$23:$F$1022,'3 Decision Tree'!$E$23:$E$1022) | D34: 0.8 | E34: 0.9 | F34: =COUNTIFS('3 Decision Tree'!$D$23:$D$1022,">="&D34,'3 Decision Tree'!$D$23:$D$1022,"<"&E34) | G34: =COUNTIFS('3 Decision Tree'!$D$23:$D$1022,">="&D34,'3 Decision Tree'!$D$23:$D$1022,"<"&E34,'3 Decision Tree'!$E$23:$E$1022,1) | H34: =F34-G34 | I34: =SUM($G$33:G34)/SUM($G$33:$G$42) | J34: =SUM($H$33:H34)/SUM($H$33:$H$42) | K34: =I34-J34
B35: AUC | C35: =(C34-C32*(C32+1)/2)/(C32*C33) | D35: 0.7 | E35: 0.8 | F35: =COUNTIFS('3 Decision Tree'!$D$23:$D$1022,">="&D35,'3 Decision Tree'!$D$23:$D$1022,"<"&E35) | G35: =COUNTIFS('3 Decision Tree'!$D$23:$D$1022,">="&D35,'3 Decision Tree'!$D$23:$D$1022,"<"&E35,'3 Decision Tree'!$E$23:$E$1022,1) | H35: =F35-G35 | I35: =SUM($G$33:G35)/SUM($G$33:$G$42) | J35: =SUM($H$33:H35)/SUM($H$33:$H$42) | K35: =I35-J35
B36: Gini = 2 × AUC − 1 | C36: =2*C35-1 | D36: 0.6 | E36: 0.7 | F36: =COUNTIFS('3 Decision Tree'!$D$23:$D$1022,">="&D36,'3 Decision Tree'!$D$23:$D$1022,"<"&E36) | G36: =COUNTIFS('3 Decision Tree'!$D$23:$D$1022,">="&D36,'3 Decision Tree'!$D$23:$D$1022,"<"&E36,'3 Decision Tree'!$E$23:$E$1022,1) | H36: =F36-G36 | I36: =SUM($G$33:G36)/SUM($G$33:$G$42) | J36: =SUM($H$33:H36)/SUM($H$33:$H$42) | K36: =I36-J36
D37: 0.5 | E37: 0.6 | F37: =COUNTIFS('3 Decision Tree'!$D$23:$D$1022,">="&D37,'3 Decision Tree'!$D$23:$D$1022,"<"&E37) | G37: =COUNTIFS('3 Decision Tree'!$D$23:$D$1022,">="&D37,'3 Decision Tree'!$D$23:$D$1022,"<"&E37,'3 Decision Tree'!$E$23:$E$1022,1) | H37: =F37-G37 | I37: =SUM($G$33:G37)/SUM($G$33:$G$42) | J37: =SUM($H$33:H37)/SUM($H$33:$H$42) | K37: =I37-J37
D38: 0.4 | E38: 0.5 | F38: =COUNTIFS('3 Decision Tree'!$D$23:$D$1022,">="&D38,'3 Decision Tree'!$D$23:$D$1022,"<"&E38) | G38: =COUNTIFS('3 Decision Tree'!$D$23:$D$1022,">="&D38,'3 Decision Tree'!$D$23:$D$1022,"<"&E38,'3 Decision Tree'!$E$23:$E$1022,1) | H38: =F38-G38 | I38: =SUM($G$33:G38)/SUM($G$33:$G$42) | J38: =SUM($H$33:H38)/SUM($H$33:$H$42) | K38: =I38-J38
D39: 0.3 | E39: 0.4 | F39: =COUNTIFS('3 Decision Tree'!$D$23:$D$1022,">="&D39,'3 Decision Tree'!$D$23:$D$1022,"<"&E39) | G39: =COUNTIFS('3 Decision Tree'!$D$23:$D$1022,">="&D39,'3 Decision Tree'!$D$23:$D$1022,"<"&E39,'3 Decision Tree'!$E$23:$E$1022,1) | H39: =F39-G39 | I39: =SUM($G$33:G39)/SUM($G$33:$G$42) | J39: =SUM($H$33:H39)/SUM($H$33:$H$42) | K39: =I39-J39
D40: 0.2 | E40: 0.3 | F40: =COUNTIFS('3 Decision Tree'!$D$23:$D$1022,">="&D40,'3 Decision Tree'!$D$23:$D$1022,"<"&E40) | G40: =COUNTIFS('3 Decision Tree'!$D$23:$D$1022,">="&D40,'3 Decision Tree'!$D$23:$D$1022,"<"&E40,'3 Decision Tree'!$E$23:$E$1022,1) | H40: =F40-G40 | I40: =SUM($G$33:G40)/SUM($G$33:$G$42) | J40: =SUM($H$33:H40)/SUM($H$33:$H$42) | K40: =I40-J40
D41: 0.1 | E41: 0.2 | F41: =COUNTIFS('3 Decision Tree'!$D$23:$D$1022,">="&D41,'3 Decision Tree'!$D$23:$D$1022,"<"&E41) | G41: =COUNTIFS('3 Decision Tree'!$D$23:$D$1022,">="&D41,'3 Decision Tree'!$D$23:$D$1022,"<"&E41,'3 Decision Tree'!$E$23:$E$1022,1) | H41: =F41-G41 | I41: =SUM($G$33:G41)/SUM($G$33:$G$42) | J41: =SUM($H$33:H41)/SUM($H$33:$H$42) | K41: =I41-J41
D42: 0 | E42: 0.1 | F42: =COUNTIFS('3 Decision Tree'!$D$23:$D$1022,">="&D42,'3 Decision Tree'!$D$23:$D$1022,"<="&E42) | G42: =COUNTIFS('3 Decision Tree'!$D$23:$D$1022,">="&D42,'3 Decision Tree'!$D$23:$D$1022,"<="&E42,'3 Decision Tree'!$E$23:$E$1022,1) | H42: =F42-G42 | I42: =SUM($G$33:G42)/SUM($G$33:$G$42) | J42: =SUM($H$33:H42)/SUM($H$33:$H$42) | K42: =I42-J42
I43: KS = | J43: =MAX(K33:K42) | K43: widest gap
B51: XGBoost
B52: Bad customers (defaulted) | C52: =SUM('4 XGBoost'!$D$23:$D$1022) | D52: From | E52: To | F52: Customers | G52: Bad | H52: Good | I52: Cum % of bad | J52: Cum % of good | K52: Gap
B53: Good customers | C53: =COUNT('4 XGBoost'!$D$23:$D$1022)-C52 | D53: 0.9 | E53: 1 | F53: =COUNTIFS('4 XGBoost'!$C$23:$C$1022,">="&D53,'4 XGBoost'!$C$23:$C$1022,"<"&E53) | G53: =COUNTIFS('4 XGBoost'!$C$23:$C$1022,">="&D53,'4 XGBoost'!$C$23:$C$1022,"<"&E53,'4 XGBoost'!$D$23:$D$1022,1) | H53: =F53-G53 | I53: =SUM($G$53:G53)/SUM($G$53:$G$62) | J53: =SUM($H$53:H53)/SUM($H$53:$H$62) | K53: =I53-J53
B54: Sum of the bad customers' ranks | C54: =SUMPRODUCT('4 XGBoost'!$E$23:$E$1022,'4 XGBoost'!$D$23:$D$1022) | D54: 0.8 | E54: 0.9 | F54: =COUNTIFS('4 XGBoost'!$C$23:$C$1022,">="&D54,'4 XGBoost'!$C$23:$C$1022,"<"&E54) | G54: =COUNTIFS('4 XGBoost'!$C$23:$C$1022,">="&D54,'4 XGBoost'!$C$23:$C$1022,"<"&E54,'4 XGBoost'!$D$23:$D$1022,1) | H54: =F54-G54 | I54: =SUM($G$53:G54)/SUM($G$53:$G$62) | J54: =SUM($H$53:H54)/SUM($H$53:$H$62) | K54: =I54-J54
B55: AUC | C55: =(C54-C52*(C52+1)/2)/(C52*C53) | D55: 0.7 | E55: 0.8 | F55: =COUNTIFS('4 XGBoost'!$C$23:$C$1022,">="&D55,'4 XGBoost'!$C$23:$C$1022,"<"&E55) | G55: =COUNTIFS('4 XGBoost'!$C$23:$C$1022,">="&D55,'4 XGBoost'!$C$23:$C$1022,"<"&E55,'4 XGBoost'!$D$23:$D$1022,1) | H55: =F55-G55 | I55: =SUM($G$53:G55)/SUM($G$53:$G$62) | J55: =SUM($H$53:H55)/SUM($H$53:$H$62) | K55: =I55-J55
B56: Gini = 2 × AUC − 1 | C56: =2*C55-1 | D56: 0.6 | E56: 0.7 | F56: =COUNTIFS('4 XGBoost'!$C$23:$C$1022,">="&D56,'4 XGBoost'!$C$23:$C$1022,"<"&E56) | G56: =COUNTIFS('4 XGBoost'!$C$23:$C$1022,">="&D56,'4 XGBoost'!$C$23:$C$1022,"<"&E56,'4 XGBoost'!$D$23:$D$1022,1) | H56: =F56-G56 | I56: =SUM($G$53:G56)/SUM($G$53:$G$62) | J56: =SUM($H$53:H56)/SUM($H$53:$H$62) | K56: =I56-J56
D57: 0.5 | E57: 0.6 | F57: =COUNTIFS('4 XGBoost'!$C$23:$C$1022,">="&D57,'4 XGBoost'!$C$23:$C$1022,"<"&E57) | G57: =COUNTIFS('4 XGBoost'!$C$23:$C$1022,">="&D57,'4 XGBoost'!$C$23:$C$1022,"<"&E57,'4 XGBoost'!$D$23:$D$1022,1) | H57: =F57-G57 | I57: =SUM($G$53:G57)/SUM($G$53:$G$62) | J57: =SUM($H$53:H57)/SUM($H$53:$H$62) | K57: =I57-J57
D58: 0.4 | E58: 0.5 | F58: =COUNTIFS('4 XGBoost'!$C$23:$C$1022,">="&D58,'4 XGBoost'!$C$23:$C$1022,"<"&E58) | G58: =COUNTIFS('4 XGBoost'!$C$23:$C$1022,">="&D58,'4 XGBoost'!$C$23:$C$1022,"<"&E58,'4 XGBoost'!$D$23:$D$1022,1) | H58: =F58-G58 | I58: =SUM($G$53:G58)/SUM($G$53:$G$62) | J58: =SUM($H$53:H58)/SUM($H$53:$H$62) | K58: =I58-J58
D59: 0.3 | E59: 0.4 | F59: =COUNTIFS('4 XGBoost'!$C$23:$C$1022,">="&D59,'4 XGBoost'!$C$23:$C$1022,"<"&E59) | G59: =COUNTIFS('4 XGBoost'!$C$23:$C$1022,">="&D59,'4 XGBoost'!$C$23:$C$1022,"<"&E59,'4 XGBoost'!$D$23:$D$1022,1) | H59: =F59-G59 | I59: =SUM($G$53:G59)/SUM($G$53:$G$62) | J59: =SUM($H$53:H59)/SUM($H$53:$H$62) | K59: =I59-J59
D60: 0.2 | E60: 0.3 | F60: =COUNTIFS('4 XGBoost'!$C$23:$C$1022,">="&D60,'4 XGBoost'!$C$23:$C$1022,"<"&E60) | G60: =COUNTIFS('4 XGBoost'!$C$23:$C$1022,">="&D60,'4 XGBoost'!$C$23:$C$1022,"<"&E60,'4 XGBoost'!$D$23:$D$1022,1) | H60: =F60-G60 | I60: =SUM($G$53:G60)/SUM($G$53:$G$62) | J60: =SUM($H$53:H60)/SUM($H$53:$H$62) | K60: =I60-J60
D61: 0.1 | E61: 0.2 | F61: =COUNTIFS('4 XGBoost'!$C$23:$C$1022,">="&D61,'4 XGBoost'!$C$23:$C$1022,"<"&E61) | G61: =COUNTIFS('4 XGBoost'!$C$23:$C$1022,">="&D61,'4 XGBoost'!$C$23:$C$1022,"<"&E61,'4 XGBoost'!$D$23:$D$1022,1) | H61: =F61-G61 | I61: =SUM($G$53:G61)/SUM($G$53:$G$62) | J61: =SUM($H$53:H61)/SUM($H$53:$H$62) | K61: =I61-J61
...
