Workbook

Sheet Portfolio
A1: Portfolio: five NSE large caps, equal-weighted
A2: Portfolio value (Rs) | B2: 10000000
A3: Prices as of | B3: 25 Sep 2026
A4: Source: Yahoo Finance adjusted close, downloaded 26 Sep 2026 via yfinance, .NS tickers
A6: Ticker | B6: Company | C6: Sector | D6: Weight | E6: Last close (Rs) | F6: Allocation (Rs) | G6: Shares (approx) | H6: Daily vol | I6: Annual vol | J6: Mean daily return
A7: RELIANCE.NS | B7: Reliance Industries | C7: Energy / Conglomerate | D7: 0.2 | E7: 1226 | F7: =D7*$B$2 | G7: =F7/E7 | H7: =Inputs!C7 | I7: =H7*SQRT(252) | J7: =Inputs!B7
A8: HDFCBANK.NS | B8: HDFC Bank | C8: Private Bank | D8: 0.2 | E8: 735.6 | F8: =D8*$B$2 | G8: =F8/E8 | H8: =Inputs!C8 | I8: =H8*SQRT(252) | J8: =Inputs!B8
A9: TCS.NS | B9: Tata Consultancy Services | C9: IT Services | D9: 0.2 | E9: 2082 | F9: =D9*$B$2 | G9: =F9/E9 | H9: =Inputs!C9 | I9: =H9*SQRT(252) | J9: =Inputs!B9
A10: BHARTIARTL.NS | B10: Bharti Airtel | C10: Telecom | D10: 0.2 | E10: 1785.4 | F10: =D10*$B$2 | G10: =F10/E10 | H10: =Inputs!C10 | I10: =H10*SQRT(252) | J10: =Inputs!B10
A11: ICICIBANK.NS | B11: ICICI Bank | C11: Private Bank | D11: 0.2 | E11: 1326.8 | F11: =D11*$B$2 | G11: =F11/E11 | H11: =Inputs!C11 | I11: =H11*SQRT(252) | J11: =Inputs!B11
A12: Total | D12: =SUM(D7:D11) | F12: =SUM(F7:F11)
A14: Concentration
A15: Bank exposure (HDFC + ICICI) | B15: =D8+D11
A16: Largest single name | B16: =MAX(D7:D11)

Sheet Returns
A1: Date | B1: RELIANCE.NS return | C1: HDFCBANK.NS return | D1: TCS.NS return | E1: BHARTIARTL.NS return | F1: ICICIBANK.NS return | G1: Portfolio return | H1: Portfolio P&L (Rs)
A2: 45562 | B2: =Prices!B3/Prices!B2-1 | C2: =Prices!C3/Prices!C2-1 | D2: =Prices!D3/Prices!D2-1 | E2: =Prices!E3/Prices!E2-1 | F2: =Prices!F3/Prices!F2-1 | G2: =B2*Portfolio!$D$7+C2*Portfolio!$D$8+D2*Portfolio!$D$9+E2*Portfolio!$D$10+F2*Portfolio!$D$11 | H2: =G2*Portfolio!$B$2
A3: 45565 | B3: =Prices!B4/Prices!B3-1 | C3: =Prices!C4/Prices!C3-1 | D3: =Prices!D4/Prices!D3-1 | E3: =Prices!E4/Prices!E3-1 | F3: =Prices!F4/Prices!F3-1 | G3: =B3*Portfolio!$D$7+C3*Portfolio!$D$8+D3*Portfolio!$D$9+E3*Portfolio!$D$10+F3*Portfolio!$D$11 | H3: =G3*Portfolio!$B$2
A4: 45566 | B4: =Prices!B5/Prices!B4-1 | C4: =Prices!C5/Prices!C4-1 | D4: =Prices!D5/Prices!D4-1 | E4: =Prices!E5/Prices!E4-1 | F4: =Prices!F5/Prices!F4-1 | G4: =B4*Portfolio!$D$7+C4*Portfolio!$D$8+D4*Portfolio!$D$9+E4*Portfolio!$D$10+F4*Portfolio!$D$11 | H4: =G4*Portfolio!$B$2
A5: 45568 | B5: =Prices!B6/Prices!B5-1 | C5: =Prices!C6/Prices!C5-1 | D5: =Prices!D6/Prices!D5-1 | E5: =Prices!E6/Prices!E5-1 | F5: =Prices!F6/Prices!F5-1 | G5: =B5*Portfolio!$D$7+C5*Portfolio!$D$8+D5*Portfolio!$D$9+E5*Portfolio!$D$10+F5*Portfolio!$D$11 | H5: =G5*Portfolio!$B$2
A6: 45569 | B6: =Prices!B7/Prices!B6-1 | C6: =Prices!C7/Prices!C6-1 | D6: =Prices!D7/Prices!D6-1 | E6: =Prices!E7/Prices!E6-1 | F6: =Prices!F7/Prices!F6-1 | G6: =B6*Portfolio!$D$7+C6*Portfolio!$D$8+D6*Portfolio!$D$9+E6*Portfolio!$D$10+F6*Portfolio!$D$11 | H6: =G6*Portfolio!$B$2
A7: 45572 | B7: =Prices!B8/Prices!B7-1 | C7: =Prices!C8/Prices!C7-1 | D7: =Prices!D8/Prices!D7-1 | E7: =Prices!E8/Prices!E7-1 | F7: =Prices!F8/Prices!F7-1 | G7: =B7*Portfolio!$D$7+C7*Portfolio!$D$8+D7*Portfolio!$D$9+E7*Portfolio!$D$10+F7*Portfolio!$D$11 | H7: =G7*Portfolio!$B$2
A8: 45573 | B8: =Prices!B9/Prices!B8-1 | C8: =Prices!C9/Prices!C8-1 | D8: =Prices!D9/Prices!D8-1 | E8: =Prices!E9/Prices!E8-1 | F8: =Prices!F9/Prices!F8-1 | G8: =B8*Portfolio!$D$7+C8*Portfolio!$D$8+D8*Portfolio!$D$9+E8*Portfolio!$D$10+F8*Portfolio!$D$11 | H8: =G8*Portfolio!$B$2
A9: 45574 | B9: =Prices!B10/Prices!B9-1 | C9: =Prices!C10/Prices!C9-1 | D9: =Prices!D10/Prices!D9-1 | E9: =Prices!E10/Prices!E9-1 | F9: =Prices!F10/Prices!F9-1 | G9: =B9*Portfolio!$D$7+C9*Portfolio!$D$8+D9*Portfolio!$D$9+E9*Portfolio!$D$10+F9*Portfolio!$D$11 | H9: =G9*Portfolio!$B$2
A10: 45575 | B10: =Prices!B11/Prices!B10-1 | C10: =Prices!C11/Prices!C10-1 | D10: =Prices!D11/Prices!D10-1 | E10: =Prices!E11/Prices!E10-1 | F10: =Prices!F11/Prices!F10-1 | G10: =B10*Portfolio!$D$7+C10*Portfolio!$D$8+D10*Portfolio!$D$9+E10*Portfolio!$D$10+F10*Portfolio!$D$11 | H10: =G10*Portfolio!$B$2
A11: 45576 | B11: =Prices!B12/Prices!B11-1 | C11: =Prices!C12/Prices!C11-1 | D11: =Prices!D12/Prices!D11-1 | E11: =Prices!E12/Prices!E11-1 | F11: =Prices!F12/Prices!F11-1 | G11: =B11*Portfolio!$D$7+C11*Portfolio!$D$8+D11*Portfolio!$D$9+E11*Portfolio!$D$10+F11*Portfolio!$D$11 | H11: =G11*Portfolio!$B$2
A12: 45579 | B12: =Prices!B13/Prices!B12-1 | C12: =Prices!C13/Prices!C12-1 | D12: =Prices!D13/Prices!D12-1 | E12: =Prices!E13/Prices!E12-1 | F12: =Prices!F13/Prices!F12-1 | G12: =B12*Portfolio!$D$7+C12*Portfolio!$D$8+D12*Portfolio!$D$9+E12*Portfolio!$D$10+F12*Portfolio!$D$11 | H12: =G12*Portfolio!$B$2
A13: 45580 | B13: =Prices!B14/Prices!B13-1 | C13: =Prices!C14/Prices!C13-1 | D13: =Prices!D14/Prices!D13-1 | E13: =Prices!E14/Prices!E13-1 | F13: =Prices!F14/Prices!F13-1 | G13: =B13*Portfolio!$D$7+C13*Portfolio!$D$8+D13*Portfolio!$D$9+E13*Portfolio!$D$10+F13*Portfolio!$D$11 | H13: =G13*Portfolio!$B$2
... A500: 46290 | B500: =Prices!B501/Prices!B500-1 | C500: =Prices!C501/Prices!C500-1 | D500: =Prices!D501/Prices!D500-1 | E500: =Prices!E501/Prices!E500-1 | F500: =Prices!F501/Prices!F500-1 | G500: =B500*Portfolio!$D$7+C500*Portfolio!$D$8+D500*Portfolio!$D$9+E500*Portfolio!$D$10+F500*Portfolio!$D$11 | H500: =G500*Portfolio!$B$2

Sheet Inputs
A1: Inputs estimated from two years of daily log returns
A2: Window 2024-09-26 to 2026-09-25, 499 daily returns
A3: Mean, vol, correlation, covariance and Cholesky are computed in Python from the Prices sheet and pasted as inputs (blue).
A6: Ticker | B6: Mean daily log return | C6: Daily vol (stdev) | D6: Annual vol
A7: RELIANCE.NS | B7: -0.00038425206 | C7: 0.013139733 | D7: =C7*SQRT(252)
A8: HDFCBANK.NS | B8: -0.00032593333 | C8: 0.012414642 | D8: =C8*SQRT(252)
A9: TCS.NS | B9: -0.0013025231 | C9: 0.015639582 | D9: =C9*SQRT(252)
A10: BHARTIARTL.NS | B10: 5.7862826e-05 | C10: 0.013122253 | D10: =C10*SQRT(252)
A11: ICICIBANK.NS | B11: 2.8832056e-05 | C11: 0.011567753 | D11: =C11*SQRT(252)
A13: Correlation matrix
B14: RELIANCE.NS | C14: HDFCBANK.NS | D14: TCS.NS | E14: BHARTIARTL.NS | F14: ICICIBANK.NS
A15: RELIANCE.NS | B15: 1 | C15: 0.40897622 | D15: 0.24551907 | E15: 0.30590698 | F15: 0.27412072
A16: HDFCBANK.NS | B16: 0.40897622 | C16: 1 | D16: 0.18963519 | E16: 0.27450771 | F16: 0.52735304
A17: TCS.NS | B17: 0.24551907 | C17: 0.18963519 | D17: 1 | E17: 0.16217886 | F17: 0.16661422
A18: BHARTIARTL.NS | B18: 0.30590698 | C18: 0.27450771 | D18: 0.16217886 | E18: 1 | F18: 0.26897172
A19: ICICIBANK.NS | B19: 0.27412072 | C19: 0.52735304 | D19: 0.16661422 | E19: 0.26897172 | F19: 1
A21: Covariance matrix (Sigma)
B22: RELIANCE.NS | C22: HDFCBANK.NS | D22: TCS.NS | E22: BHARTIARTL.NS | F22: ICICIBANK.NS
A23: RELIANCE.NS | B23: 0.00017265258 | C23: 6.671428e-05 | D23: 5.0454152e-05 | E23: 5.2745369e-05 | F23: 4.1665578e-05
A24: HDFCBANK.NS | B24: 6.671428e-05 | C24: 0.00015412334 | D24: 3.6819532e-05 | E24: 4.4719522e-05 | F24: 7.5732913e-05
A25: TCS.NS | B25: 5.0454152e-05 | C25: 3.6819532e-05 | D25: 0.00024459651 | E25: 3.3283407e-05 | F25: 3.0142982e-05
A26: BHARTIARTL.NS | B26: 5.2745369e-05 | C26: 4.4719522e-05 | D26: 3.3283407e-05 | E26: 0.00017219352 | F26: 4.0828557e-05
A27: ICICIBANK.NS | B27: 4.1665578e-05 | C27: 7.5732913e-05 | D27: 3.0142982e-05 | E27: 4.0828557e-05 | F27: 0.00013381291
A29: Cholesky factor L (Sigma = L x L')
B30: RELIANCE.NS | C30: HDFCBANK.NS | D30: TCS.NS | E30: BHARTIARTL.NS | F30: ICICIBANK.NS
A31: RELIANCE.NS | B31: 0.013139733 | C31: 0 | D31: 0 | E31: 0 | F31: 0
A32: HDFCBANK.NS | B32: 0.0050772934 | C32: 0.01132892 | D32: 0 | E32: 0 | F32: 0
A33: TCS.NS | B33: 0.0038398156 | C33: 0.0015291538 | D33: 0.015083568 | E33: 0 | F33: 0
A34: BHARTIARTL.NS | B34: 0.0040141888 | C34: 0.0021483343 | D34: 0.00096691507 | E34: 0.012269048 | F34: 0
A35: ICICIBANK.NS | B35: 0.0031709608 | C35: 0.0052637863 | D35: 0.00065753263 | E35: 0.0013167746 | F35: 0.0096893872
A37: Weight products w(i) x w(j), used for portfolio variance
B38: RELIANCE.NS | C38: HDFCBANK.NS | D38: TCS.NS | E38: BHARTIARTL.NS | F38: ICICIBANK.NS
A39: RELIANCE.NS | B39: =Portfolio!$D$7*Portfolio!$D$7 | C39: =Portfolio!$D$7*Portfolio!$D$8 | D39: =Portfolio!$D$7*Portfolio!$D$9 | E39: =Portfolio!$D$7*Portfolio!$D$10 | F39: =Portfolio!$D$7*Portfolio!$D$11
A40: HDFCBANK.NS | B40: =Portfolio!$D$8*Portfolio!$D$7 | C40: =Portfolio!$D$8*Portfolio!$D$8 | D40: =Portfolio!$D$8*Portfolio!$D$9 | E40: =Portfolio!$D$8*Portfolio!$D$10 | F40: =Portfolio!$D$8*Portfolio!$D$11
A41: TCS.NS | B41: =Portfolio!$D$9*Portfolio!$D$7 | C41: =Portfolio!$D$9*Portfolio!$D$8 | D41: =Portfolio!$D$9*Portfolio!$D$9 | E41: =Portfolio!$D$9*Portfolio!$D$10 | F41: =Portfolio!$D$9*Portfolio!$D$11
A42: BHARTIARTL.NS | B42: =Portfolio!$D$10*Portfolio!$D$7 | C42: =Portfolio!$D$10*Portfolio!$D$8 | D42: =Portfolio!$D$10*Portfolio!$D$9 | E42: =Portfolio!$D$10*Portfolio!$D$10 | F42: =Portfolio!$D$10*Portfolio!$D$11
A43: ICICIBANK.NS | B43: =Portfolio!$D$11*Portfolio!$D$7 | C43: =Portfolio!$D$11*Portfolio!$D$8 | D43: =Portfolio!$D$11*Portfolio!$D$9 | E43: =Portfolio!$D$11*Portfolio!$D$10 | F43: =Portfolio!$D$11*Portfolio!$D$11
A45: Portfolio daily vol = sqrt(sum of Sigma x weight products) | B45: =SQRT(SUMPRODUCT(B23:F27,B39:F43))
A46: Portfolio mean daily return = sum of weight x mean | B46: =SUMPRODUCT(Portfolio!D7:D11,B7:B11)

Sheet VaR Results
A1: One-day VaR and CVaR, three methods
A2: Portfolio value (Rs) | B2: =Portfolio!B2
A3: Historical sample (days) | B3: =COUNT(Returns!H2:H500)
A4: Monte Carlo paths | B4: 10000
A5: Monte Carlo seed | B5: 42
A7: 1. Historical VaR: every actual daily portfolio P&L over the window (Returns sheet)
A8: Confidence | B8: VaR (Rs) | C8: VaR % | D8: CVaR (Rs) | E8: CVaR % | F8: Days in tail | G8: Worst day (Rs) | H8: Worst day date
A9: 0.95 | B9: =-PERCENTILE(Returns!$H$2:$H$500,1-A9) | C9: =B9/$B$2 | D9: =-AVERAGEIF(Returns!$H$2:$H$500,"<="&-B9) | E9: =D9/$B$2 | F9: =COUNTIF(Returns!$H$2:$H$500,"<="&-B9) | G9: =MIN(Returns!$H$2:$H$500) | H9: =INDEX(Returns!$A$2:$A$500,MATCH(MIN(Returns!$H$2:$H$500),Returns!$H$2:$H$500,0))
A10: 0.99 | B10: =-PERCENTILE(Returns!$H$2:$H$500,1-A10) | C10: =B10/$B$2 | D10: =-AVERAGEIF(Returns!$H$2:$H$500,"<="&-B10) | E10: =D10/$B$2 | F10: =COUNTIF(Returns!$H$2:$H$500,"<="&-B10) | G10: =MIN(Returns!$H$2:$H$500) | H10: =INDEX(Returns!$A$2:$A$500,MATCH(MIN(Returns!$H$2:$H$500),Returns!$H$2:$H$500,0))
A13: 2. Monte Carlo VaR: 10,000 simulated one-day P&L paths (Paths sheet)
A14: Confidence | B14: VaR (Rs) | C14: VaR % | D14: CVaR (Rs) | E14: CVaR % | F14: Paths in tail | G14: Worst path (Rs)
A15: 0.95 | B15: =-PERCENTILE(Paths!$B$2:$B$10001,1-A15) | C15: =B15/$B$2 | D15: =-AVERAGEIF(Paths!$B$2:$B$10001,"<="&-B15) | E15: =D15/$B$2 | F15: =COUNTIF(Paths!$B$2:$B$10001,"<="&-B15) | G15: =MIN(Paths!$B$2:$B$10001)
A16: 0.99 | B16: =-PERCENTILE(Paths!$B$2:$B$10001,1-A16) | C16: =B16/$B$2 | D16: =-AVERAGEIF(Paths!$B$2:$B$10001,"<="&-B16) | E16: =D16/$B$2 | F16: =COUNTIF(Paths!$B$2:$B$10001,"<="&-B16) | G16: =MIN(Paths!$B$2:$B$10001)
A19: 3. Parametric (normal) VaR: closed form from portfolio mean and vol (Inputs sheet)
A20: Confidence | B20: VaR (Rs) | C20: VaR % | D20: CVaR (Rs) | E20: CVaR % | F20: z
A21: 0.95 | B21: =-$B$2*(Inputs!$B$46+F21*Inputs!$B$45) | C21: =B21/$B$2 | D21: =-$B$2*(Inputs!$B$46-Inputs!$B$45*NORMDIST(F21,0,1,FALSE)/(1-A21)) | E21: =D21/$B$2 | F21: =NORMSINV(1-A21)
A22: 0.99 | B22: =-$B$2*(Inputs!$B$46+F22*Inputs!$B$45) | C22: =B22/$B$2 | D22: =-$B$2*(Inputs!$B$46-Inputs!$B$45*NORMDIST(F22,0,1,FALSE)/(1-A22)) | E22: =D22/$B$2 | F22: =NORMSINV(1-A22)
A25: Side by side
A26: Measure | B26: Historical | C26: Monte Carlo | D26: Parametric | E26: Hist vs MC
A27: 95% VaR | B27: =B9 | C27: =B15 | D27: =B21 | E27: =B27/C27-1
A28: 95% CVaR | B28: =D9 | C28: =D15 | D28: =D21 | E28: =B28/C28-1
A29: 99% VaR | B29: =B10 | C29: =B16 | D29: =B22 | E29: =B29/C29-1
A30: 99% CVaR | B30: =D10 | C30: =D16 | D30: =D22 | E30: =B30/C30-1
A32: How to read
A33: Historical VaR sorts the actual daily P&L on the Returns sheet and reads the loss at the 5th or 1st percentile. No distribution is assumed.
A34: Monte Carlo VaR does the same on 10,000 simulated days drawn from a normal distribution with the historical mean, vol and correlation.
A35: Parametric VaR is the closed-form normal answer, as a check that the simulation reproduces its own inputs.
A36: CVaR is the average loss on the days or paths that lost more than VaR.
A37: Historical CVaR is larger than Monte Carlo CVaR. Real NSE days have fatter tails than a normal distribution.
A38: Change weights on the Portfolio sheet: historical and parametric recalculate. Monte Carlo needs a rerun of mc_var.py to refresh Paths.

Sheet Path Walkthrough
A1: How one path becomes a rupee P&L: first six of the 10,000 paths
A2: Step 1: draw five independent standard normals Z (blue, seed 42). Step 2: log return = mu + Z x L' (Cholesky on Inputs sheet), which puts the historical correlation back in.
A3: Step 3: simple return = exp(log return) - 1. Step 4: rupee P&L = simple return x weight x portfolio value. Step 5: path P&L = sum over the five stocks. Paths sheet holds 10,000 of these.
A5: PATH 1 | C5: Path P&L (Rs) | D5: =SUM(F7:F11) | E5: Paths sheet | F5: =Paths!B2
A6: Stock | B6: Z draw | C6: Log return | D6: Simple return | E6: Weight x value (Rs) | F6: Stock P&L (Rs) | G6: Formula for log return
A7: RELIANCE | B7: 0.30471708 | C7: =Inputs!$B$7+$B$7*Inputs!B$31 | D7: =EXP(C7)-1 | E7: =Portfolio!$D$7*Portfolio!$B$2 | F7: =D7*E7 | G7: mu + Z1 x L(1,1)
A8: HDFCBANK | B8: -1.0399841 | C8: =Inputs!$B$8+$B$7*Inputs!B$32+$B$8*Inputs!C$32 | D8: =EXP(C8)-1 | E8: =Portfolio!$D$8*Portfolio!$B$2 | F8: =D8*E8 | G8: mu + Z1 x L(2,1) + Z2 x L(2,2)
A9: TCS | B9: 0.7504512 | C9: =Inputs!$B$9+$B$7*Inputs!B$33+$B$8*Inputs!C$33+$B$9*Inputs!D$33 | D9: =EXP(C9)-1 | E9: =Portfolio!$D$9*Portfolio!$B$2 | F9: =D9*E9 | G9: mu + Z1 x L(3,1) + Z2 x L(3,2) + Z3 x L(3,3)
A10: BHARTIARTL | B10: 0.94056472 | C10: =Inputs!$B$10+$B$7*Inputs!B$34+$B$8*Inputs!C$34+$B$9*Inputs!D$34+$B$10*Inputs!E$34 | D10: =EXP(C10)-1 | E10: =Portfolio!$D$10*Portfolio!$B$2 | F10: =D10*E10 | G10: mu + Z1 x L(4,1) + Z2 x L(4,2) + Z3 x L(4,3) + Z4 x L(4,4)
A11: ICICIBANK | B11: -1.9510352 | C11: =Inputs!$B$11+$B$7*Inputs!B$35+$B$8*Inputs!C$35+$B$9*Inputs!D$35+$B$10*Inputs!E$35+$B$11*Inputs!F$35 | D11: =EXP(C11)-1 | E11: =Portfolio!$D$11*Portfolio!$B$2 | F11: =D11*E11 | G11: mu + Z1 x L(5,1) + Z2 x L(5,2) + Z3 x L(5,3) + Z4 x L(5,4) + Z5 x L(5,5)
A15: PATH 2 | C15: Path P&L (Rs) | D15: =SUM(F17:F21) | E15: Paths sheet | F15: =Paths!B3
A16: Stock | B16: Z draw | C16: Log return | D16: Simple return | E16: Weight x value (Rs) | F16: Stock P&L (Rs) | G16: Formula for log return
A17: RELIANCE | B17: -1.3021795 | C17: =Inputs!$B$7+$B$17*Inputs!B$31 | D17: =EXP(C17)-1 | E17: =Portfolio!$D$7*Portfolio!$B$2 | F17: =D17*E17 | G17: mu + Z1 x L(1,1)
A18: HDFCBANK | B18: 0.1278404 | C18: =Inputs!$B$8+$B$17*Inputs!B$32+$B$18*Inputs!C$32 | D18: =EXP(C18)-1 | E18: =Portfolio!$D$8*Portfolio!$B$2 | F18: =D18*E18 | G18: mu + Z1 x L(2,1) + Z2 x L(2,2)
A19: TCS | B19: -0.31624259 | C19: =Inputs!$B$9+$B$17*Inputs!B$33+$B$18*Inputs!C$33+$B$19*Inputs!D$33 | D19: =EXP(C19)-1 | E19: =Portfolio!$D$9*Portfolio!$B$2 | F19: =D19*E19 | G19: mu + Z1 x L(3,1) + Z2 x L(3,2) + Z3 x L(3,3)
A20: BHARTIARTL | B20: -0.016801158 | C20: =Inputs!$B$10+$B$17*Inputs!B$34+$B$18*Inputs!C$34+$B$19*Inputs!D$34+$B$20*Inputs!E$34 | D20: =EXP(C20)-1 | E20: =Portfolio!$D$10*Portfolio!$B$2 | F20: =D20*E20 | G20: mu + Z1 x L(4,1) + Z2 x L(4,2) + Z3 x L(4,3) + Z4 x L(4,4)
A21: ICICIBANK | B21: -0.85304393 | C21: =Inputs!$B$11+$B$17*Inputs!B$35+$B$18*Inputs!C$35+$B$19*Inputs!D$35+$B$20*Inputs!E$35+$B$21*Inputs!F$35 | D21: =EXP(C21)-1 | E21: =Portfolio!$D$11*Portfolio!$B$2 | F21: =D21*E21 | G21: mu + Z1 x L(5,1) + Z2 x L(5,2) + Z3 x L(5,3) + Z4 x L(5,4) + Z5 x L(5,5)
A25: PATH 3 | C25: Path P&L (Rs) | D25: =SUM(F27:F31) | E25: Paths sheet | F25: =Paths!B4
A26: Stock | B26: Z draw | C26: Log return | D26: Simple return | E26: Weight x value (Rs) | F26: Stock P&L (Rs) | G26: Formula for log return
A27: RELIANCE | B27: 0.87939797 | C27: =Inputs!$B$7+$B$27*Inputs!B$31 | D27: =EXP(C27)-1 | E27: =Portfolio!$D$7*Portfolio!$B$2 | F27: =D27*E27 | G27: mu + Z1 x L(1,1)
A28: HDFCBANK | B28: 0.77779194 | C28: =Inputs!$B$8+$B$27*Inputs!B$32+$B$28*Inputs!C$32 | D28: =EXP(C28)-1 | E28: =Portfolio!$D$8*Portfolio!$B$2 | F28: =D28*E28 | G28: mu + Z1 x L(2,1) + Z2 x L(2,2)
A29: TCS | B29: 0.066030698 | C29: =Inputs!$B$9+$B$27*Inputs!B$33+$B$28*Inputs!C$33+$B$29*Inputs!D$33 | D29: =EXP(C29)-1 | E29: =Portfolio!$D$9*Portfolio!$B$2 | F29: =D29*E29 | G29: mu + Z1 x L(3,1) + Z2 x L(3,2) + Z3 x L(3,3)
A30: BHARTIARTL | B30: 1.1272412 | C30: =Inputs!$B$10+$B$27*Inputs!B$34+$B$28*Inputs!C$34+$B$29*Inputs!D$34+$B$30*Inputs!E$34 | D30: =EXP(C30)-1 | E30: =Portfolio!$D$10*Portfolio!$B$2 | F30: =D30*E30 | G30: mu + Z1 x L(4,1) + Z2 x L(4,2) + Z3 x L(4,3) + Z4 x L(4,4)
A31: ICICIBANK | B31: 0.46750934 | C31: =Inputs!$B$11+$B$27*Inputs!B$35+$B$28*Inputs!C$35+$B$29*Inputs!D$35+$B$30*Inputs!E$35+$B$31*Inputs!F$35 | D31: =EXP(C31)-1 | E31: =Portfolio!$D$11*Portfolio!$B$2 | F31: =D31*E31 | G31: mu + Z1 x L(5,1) + Z2 x L(5,2) + Z3 x L(5,3) + Z4 x L(5,4) + Z5 x L(5,5)
A35: PATH 4 | C35: Path P&L (Rs) | D35: =SUM(F37:F41) | E35: Paths sheet | F35: =Paths!B5
A36: Stock | B36: Z draw | C36: Log return | D36: Simple return | E36: Weight x value (Rs) | F36: Stock P&L (Rs) | G36: Formula for log return
A37: RELIANCE | B37: -0.85929246 | C37: =Inputs!$B$7+$B$37*Inputs!B$31 | D37: =EXP(C37)-1 | E37: =Portfolio!$D$7*Portfolio!$B$2 | F37: =D37*E37 | G37: mu + Z1 x L(1,1)
A38: HDFCBANK | B38: 0.36875078 | C38: =Inputs!$B$8+$B$37*Inputs!B$32+$B$38*Inputs!C$32 | D38: =EXP(C38)-1 | E38: =Portfolio!$D$8*Portfolio!$B$2 | F38: =D38*E38 | G38: mu + Z1 x L(2,1) + Z2 x L(2,2)
A39: TCS | B39: -0.9588826 | C39: =Inputs!$B$9+$B$37*Inputs!B$33+$B$38*Inputs!C$33+$B$39*Inputs!D$33 | D39: =EXP(C39)-1 | E39: =Portfolio!$D$9*Portfolio!$B$2 | F39: =D39*E39 | G39: mu + Z1 x L(3,1) + Z2 x L(3,2) + Z3 x L(3,3)
A40: BHARTIARTL | B40: 0.8784503 | C40: =Inputs!$B$10+$B$37*Inputs!B$34+$B$38*Inputs!C$34+$B$39*Inputs!D$34+$B$40*Inputs!E$34 | D40: =EXP(C40)-1 | E40: =Portfolio!$D$10*Portfolio!$B$2 | F40: =D40*E40 | G40: mu + Z1 x L(4,1) + Z2 x L(4,2) + Z3 x L(4,3) + Z4 x L(4,4)
A41: ICICIBANK | B41: -0.049925911 | C41: =Inputs!$B$11+$B$37*Inputs!B$35+$B$38*Inputs!C$35+$B$39*Inputs!D$35+$B$40*Inputs!E$35+$B$41*Inputs!F$35 | D41: =EXP(C41)-1 | E41: =Portfolio!$D$11*Portfolio!$B$2 | F41: =D41*E41 | G41: mu + Z1 x L(5,1) + Z2 x L(5,2) + Z3 x L(5,3) + Z4 x L(5,4) + Z5 x L(5,5)
A45: PATH 5 | C45: Path P&L (Rs) | D45: =SUM(F47:F51) | E45: Paths sheet | F45: =Paths!B6
A46: Stock | B46: Z draw | C46: Log return | D46: Simple return | E46: Weight x value (Rs) | F46: Stock P&L (Rs) | G46: Formula for log return
A47: RELIANCE | B47: -0.18486236 | C47: =Inputs!$B$7+$B$47*Inputs!B$31 | D47: =EXP(C47)-1 | E47: =Portfolio!$D$7*Portfolio!$B$2 | F47: =D47*E47 | G47: mu + Z1 x L(1,1)
A48: HDFCBANK | B48: -0.68092954 | C48: =Inputs!$B$8+$B$47*Inputs!B$32+$B$48*Inputs!C$32 | D48: =EXP(C48)-1 | E48: =Portfolio!$D$8*Portfolio!$B$2 | F48: =D48*E48 | G48: mu + Z1 x L(2,1) + Z2 x L(2,2)
A49: TCS | B49: 1.2225413 | C49: =Inputs!$B$9+$B$47*Inputs!B$33+$B$48*Inputs!C$33+$B$49*Inputs!D$33 | D49: =EXP(C49)-1 | E49: =Portfolio!$D$9*Portfolio!$B$2 | F49: =D49*E49 | G49: mu + Z1 x L(3,1) + Z2 x L(3,2) + Z3 x L(3,3)
A50: BHARTIARTL | B50: -0.15452948 | C50: =Inputs!$B$10+$B$47*Inputs!B$34+$B$48*Inputs!C$34+$B$49*Inputs!D$34+$B$50*Inputs!E$34 | D50: =EXP(C50)-1 | E50: =Portfolio!$D$10*Portfolio!$B$2 | F50: =D50*E50 | G50: mu + Z1 x L(4,1) + Z2 x L(4,2) + Z3 x L(4,3) + Z4 x L(4,4)
A51: ICICIBANK | B51: -0.42832782 | C51: =Inputs!$B$11+$B$47*Inputs!B$35+$B$48*Inputs!C$35+$B$49*Inputs!D$35+$B$50*Inputs!E$35+$B$51*Inputs!F$35 | D51: =EXP(C51)-1 | E51: =Portfolio!$D$11*Portfolio!$B$2 | F51: =D51*E51 | G51: mu + Z1 x L(5,1) + Z2 x L(5,2) + Z3 x L(5,3) + Z4 x L(5,4) + Z5 x L(5,5)
A55: PATH 6 | C55: Path P&L (Rs) | D55: =SUM(F57:F61) | E55: Paths sheet | F55: =Paths!B7
A56: Stock | B56: Z draw | C56: Log return | D56: Simple return | E56: Weight x value (Rs) | F56: Stock P&L (Rs) | G56: Formula for log return
...

Sheet Paths
A1: Path | B1: One-day P&L (Rs)
A2: 1 | B2: -14556.68
A3: 2 | B3: -101757.99
A4: 3 | B4: 121855.88
A5: 4 | B5: -47768.72
A6: 5 | B6: -13522.04
A7: 6 | B7: 29034.61
A8: 7 | B8: 78540.05
A9: 8 | B9: 20110.85
A10: 9 | B10: 48286.38
A11: 10 | B11: 71811.07
A12: 11 | B12: -27306.54
A13: 12 | B13: -6532.9
... A10001: 10000 | B10001: 165707.11

Sheet Prices
A1: Date | B1: RELIANCE.NS | C1: HDFCBANK.NS | D1: TCS.NS | E1: BHARTIARTL.NS | F1: ICICIBANK.NS
A2: 45561 | B2: 1485.1245 | C2: 865.5172 | D2: 3987.9927 | E2: 1734.5863 | F2: 1307.8478
A3: 45562 | B3: 1513.1079 | C3: 850.5698 | D3: 4003.0439 | E3: 1698.8389 | F3: 1285.7557
A4: 45565 | B4: 1463.9325 | C4: 840.5725 | D4: 3965.6948 | E4: 1674.3053 | F4: 1252.6918
A5: 45566 | B5: 1452.2831 | C5: 837.7335 | D5: 3983.7185 | E5: 1663.679 | F5: 1254.0695
A6: 45568 | B6: 1394.9285 | C6: 816.283 | D6: 3932.4807 | E6: 1638.9495 | F6: 1236.3074
A7: 45569 | B7: 1374.6536 | C7: 804.4658 | D7: 3950.5977 | E7: 1607.0707 | F7: 1219.9722
A8: 45572 | B8: 1358.9888 | C8: 785.1265 | D8: 3969.7371 | E8: 1627.7845 | F8: 1214.2156
A9: 45573 | B9: 1385.3857 | C9: 801.2628 | D9: 3951.5273 | E9: 1623.2794 | F9: 1216.8724
A10: 45574 | B10: 1362.8307 | C10: 792.5759 | D10: 3951.248 | E10: 1643.5037 | F10: 1224.3021
A11: 45575 | B11: 1359.311 | C11: 806.7709 | D11: 3927.5103 | E11: 1643.5037 | F11: 1223.6624
A12: 45576 | B12: 1360.3521 | C12: 801.2385 | D12: 3854.8584 | E12: 1652.6121 | F12: 1203.4894
A13: 45579 | B13: 1360.7734 | C13: 819.2433 | D13: 3843.1987 | E13: 1660.6429 | F13: 1212.0999
... A501: 46290 | B501: 1226 | C501: 735.6 | D501: 2082 | E501: 1785.4 | F501: 1326.8
